Workbook
Name annual_mwh: 'FUEL PRICES'!$B$21
Name ash_capture: PARAMETERS!$B$20
Name ash_coal: PARAMETERS!$B$7
Name ash_pks: PARAMETERS!$B$8
Name aux_kwh: PARAMETERS!$B$22
Name barge_tariff: OPEX!$B$23
Name cap_exp: CAPEX!$B$21
Name cap_factor: 'FUEL PRICES'!$B$14
Name cap_mw: 'FUEL PRICES'!$B$13
Name capex_row: CAPEX!$C$27
Name carbon_price: 'FUEL PRICES'!$B$10
Name ch4_ef: PARAMETERS!$B$15
Name co2_coal: PARAMETERS!$B$13
Name co2_pks: PARAMETERS!$B$14
Name coal_price: 'FUEL PRICES'!$B$6
Name coal_usd: 'FUEL PRICES'!$B$23
Name crf: 'FUEL PRICES'!$B$22
Name crush_kwh: PARAMETERS!$B$25
Name dry_heat: PARAMETERS!$B$24
Name elec_gwp: PARAMETERS!$B$45
Name elec_mode: PARAMETERS!$B$37
Name elec_name: PARAMETERS!$B$47
Name elec_price: 'FUEL PRICES'!$B$18
Name elec_scale: PARAMETERS!$B$46
Name faba_cost: 'FUEL PRICES'!$B$16
Name fom_rate: OPEX!$B$24
Name fx: 'FUEL PRICES'!$B$5
Name land_occ: PARAMETERS!$B$27
Name lhv_coal: PARAMETERS!$B$5
Name lhv_pks: PARAMETERS!$B$6
Name life: 'FUEL PRICES'!$B$12
Name lime_per_S: PARAMETERS!$B$21
Name limestone_price: 'FUEL PRICES'!$B$15
Name n_coal: PARAMETERS!$B$11
Name n_pks: PARAMETERS!$B$12
Name n2o_ef: PARAMETERS!$B$16
Name nox_ef: PARAMETERS!$B$17
Name nox_ratio: PARAMETERS!$B$32
Name pks_price: 'FUEL PRICES'!$B$7
Name pks_price_high: 'FUEL PRICES'!$B$9
Name pks_price_low: 'FUEL PRICES'!$B$8
Name pks_upstream_ratio: PARAMETERS!$B$28
Name pks_usd: 'FUEL PRICES'!$B$24
Name pm_ratio: PARAMETERS!$B$34
Name pm25_ef: PARAMETERS!$B$19
Name ref_capex: CAPEX!$B$18
Name ref_capex_nojetty: CAPEX!$B$19
Name ref_share: CAPEX!$B$20
Name s_coal: PARAMETERS!$B$9
Name s_pks: PARAMETERS!$B$10
Name so2_ef: PARAMETERS!$B$18
Name so2_ratio: PARAMETERS!$B$33
Name stock_ch4: PARAMETERS!$B$26
Name truck_tariff: OPEX!$B$22
Name vom_pks: OPEX!$B$25
Name wacc: 'FUEL PRICES'!$B$11
Name water_cost: 'FUEL PRICES'!$B$17
Name water_int: PARAMETERS!$B$23

Sheet ABOUT
A1: PKS Co-firing at an Indonesian Coal Power Plant — LCA and TEA Workbook
A4: Study title | B4: Life cycle assessment and techno-economic assessment of palm kernel shell (PKS) co-firing in a 300 MW sub-critical PLTU unit, Java-Bali system
A5: Case study | B5: PLTU Unit #2, 300 MW sub-critical, Java-Bali (Jamali) grid, Indonesia
A6: Functional unit | B6: 1 MWh net electricity delivered to the Java-Bali grid
A7: Scenarios | B7: 0% (baseline), 5%, 10%, 20% and 30% co-firing on an energy basis
A8: Standards followed | B8: ISO 14040:2006, ISO 14044:2006, ISO 14067:2018 (product carbon footprint)
A9: LCIA method | B9: ReCiPe 2016 v1.03 midpoint (H), proxy characterisation set
A10: Background data | B10: ecoinvent 3.10 proxy factors, Indonesia-specific where available
A11: Foreground data | B11: PLTU Unit #2 operating log 2025, CEMS record 2025, fuel laboratory results (ASTM D5865/D3174/D4239), PKS delivery logistics log, company visit 17 June 2025
A12: TEA basis | B12: Real-terms 2026 IDR, 25-year evaluation, 10% WACC, NPV of incremental cost divided by NPV of delivered energy
A13: Currency | B13: Indonesian rupiah (IDR) as primary; USD shown at a stated fixed rate
A14: Model cross-check | B14: All impact results reproduce the Brightway2 model in pks-cofiring-brightway/ to within 0.01 kg CO2e/MWh
A15: Prepared by | B15: Robby Fajrino Nugraha — Sustainability Data Analyst
A16: Version | B16: 1.0 — August 2026
A18: COLOUR AND FORMAT CONVENTIONS
A19: Blue text | B19: Hardcoded input — change these to run your own case
A20: Black text | B20: Formula or calculation — do not overwrite
A21: Green text | B21: Link pulling a value from another worksheet
A22: Yellow fill | B22: Key assumption that should be reviewed before use
A24: Sheet map
A25: GOAL / SCOPE | B25: ISO 14040 goal definition, system boundary, cut-off and allocation
A26: PARAMETERS | B26: All engineering inputs with sources — the only LCA inputs you need to edit
A27: BACKGROUND / INDICATORS | B27: Background (upstream) factors and ReCiPe characterisation factors
A28: INVENTORY | B28: Per-MWh life cycle inventory, computed from PARAMETERS for every scenario
A29: IMPACT ASSESSMENT | B29: Seven midpoint categories, foreground and background split
A30: INTERPRETATION | B30: Stage contribution, uncertainty, key drivers, conclusions
A31: CAPEX / OPEX / FUEL PRICES | B31: Techno-economic inputs under Indonesian 2026 conditions
A32: CASH FLOW / LCOE | B32: 25-year discounted cash flow and levelised cost of electricity
A33: ABATEMENT COST | B33: Cost of CO2e abatement, break-even PKS price, carbon price effect
A34: SENSITIVITY | B34: Tornado analysis and a two-way PKS price x coal price grid
A35: DASHBOARD | B35: One-page summary of LCA and TEA results
A36: SOURCE GUIDE | B36: Full source list for every literal used in the workbook

Sheet GOAL
A1: GOAL DEFINITION (ISO 14040 clause 5.2)
A4: Intended application | B4: Decision support for a state utility and an independent power producer evaluating biomass co-firing as a near-term decarbonisation measure for existing coal capacity, and for the emission-reduction claim reported under the national co-firing programme.
A6: Reasons for the study | B6: Co-firing is promoted as a low-cost abatement lever, but the claimed reduction depends on how the biogenic carbon, the upstream palm burden, the efficiency penalty and the transport route are treated. The study quantifies the net effect with a transparent, reproducible model.
A8: Questions answered | B8: 1) How much does the carbon footprint of 1 MWh fall per percentage point of co-firing? 2) Which life cycle stage and which parameter governs the result? 3) Is the reduction robust to data-quality uncertainty? 4) What does the abatement cost, and at what PKS price does it stop being economic?
A10: Intended audience | B10: Plant technical and sustainability management, utility planning, the ministry programme office, and an external critical reviewer.
A12: Comparative assertion | B12: Yes — scenarios are compared with each other. No comparative assertion is disclosed to the public against a competing product; results are reported with uncertainty ranges.
A14: Limitations declared upfront | B14: Background data are ecoinvent-3.10-consistent proxies, not licensed ecoinvent processes. Plant construction and decommissioning are cut off. Direct and indirect land-use change is not modelled; PKS is treated as an economically allocated residue.
A16: Critical review | B16: Internal review performed; the workbook and the underlying Brightway2 code are released so that an external reviewer can re-run every number.

Sheet SCOPE
A1: SCOPE, SYSTEM BOUNDARY AND METHODOLOGICAL CHOICES (ISO 14044 clause 4.2.3)
A4: Function and functional unit
A5: Function | B5: Supply of dispatchable electrical energy to the Java-Bali transmission system
A6: Functional unit | B6: 1 MWh net electricity delivered to the grid
A7: Reference flow | B7: Fuel, reagents, transport and waste services required to deliver 1 MWh net
A8: Time coverage | B8: Operating year 2025; economics in real 2026 terms
A9: Geography | B9: Indonesia — plantation and mill in Sumatra/Kalimantan, plant on Java
A10: Technology | B10: 300 MW sub-critical pulverised-coal unit with ESP and wet FGD, direct co-firing through existing mills after crushing and drying
A12: System boundary — unit processes included
A13: Process | B13: Stage | C13: What it covers | D13: Included?
A14: P1_PKM | B14: Upstream | C14: Palm kernel shell at the mill gate, economically allocated (3.1% of mill revenue), including allocated plantation land occupation | D14: Included
A15: P2_Drying | B15: Upstream | C15: Drying to a target moisture content using biomass residue heat, plus crushing electricity and stockpile methane from storage | D15: Included
A16: P3_Transport | B16: Transport | C16: Road transport by 24 t diesel truck and, in the 30% case, coastal barge transport of 3 000 DWT | D16: Included
A17: P4_Handling | B17: Core | C17: Conveying, blending and milling at the plant — auxiliary electricity drawn from the grid model | D17: Included
A18: P5_Generation | B18: Core | C18: Boiler combustion of coal and PKS, FGD limestone supply, process and make-up water, stack emissions after ESP and FGD | D18: Included
A19: P6_Ash | B19: Downstream | C19: Controlled FABA landfilling of captured ash | D19: Included
A20: Plant construction | B20: Capital | C20: Civil works, boiler and turbine manufacture of the existing unit | D20: Cut off
A21: Retrofit hardware manufacture | B21: Capital | C21: Manufacture of the co-firing handling and drying equipment | D21: Cut off (assessed in the TEA only)
A22: Decommissioning | B22: End of life | C22: Dismantling and site remediation | D22: Cut off
A23: Land use change | B23: Upstream | C23: Direct and indirect LUC of the oil palm estate | D23: Excluded — residue treatment, declared as a limitation
A25: Methodological choices
A26: Choice | B26: Setting | C26: Justification
A27: Allocation | B27: Economic allocation at the palm oil mill (3.1% to PKS) | C27: PKS carries a real market price; ISO 14044 allocation hierarchy — subdivision is not possible, so allocation reflects the economic driver.
A28: Biogenic carbon | B28: Reported separately, characterisation factor 0 kg CO2e/kg | C28: ISO 14067 requires fossil and biogenic carbon to be reported separately; the shells are a short-rotation residue.
A29: Cut-off criteria | B29: 1% of mass, energy or environmental relevance per flow; 5% cumulative | C29: Standard practice; the cut-off flows are documented on the SOURCE GUIDE sheet.
A30: Electricity background | B30: Switchable — attributional average, marginal at time of use, marginal at time of construction, decarbonising 2040 | C30: Auxiliary electricity is an ex-ante modelling choice, not a measurement; the switch shows how much the choice matters.
A31: Multi-functionality of ash | B31: FABA treated as waste to controlled landfill | C31: Conservative; FABA valorisation as a cement substitute would credit the system and is not claimed.
A32: Impact categories | B32: Seven ReCiPe 2016 midpoints | C32: Climate is the decision variable; the other six test for burden shifting.
A33: Uncertainty | B33: Pedigree-matrix lognormal uncertainty, 1 000 Monte Carlo iterations, Sobol variance decomposition | C33: Data quality differs sharply between metered coal flow and literature stockpile methane.

Sheet PARAMETERS
A1: ENGINEERING PARAMETERS — the only LCA inputs you need to edit
A2: Blue values are inputs. Every downstream sheet recalculates when you change them.
A4: Parameter | B4: Value | C4: Unit | D4: Source / basis
A5: Lower heating value, coal (4200 kcal GAR) | B5: 18.626 | C5: MJ/kg | D5: Laboratory mean of 2025 sample set, ASTM D5865
A6: Lower heating value, PKS as received | B6: 17.035 | C6: MJ/kg | D6: Laboratory mean of 2025 sample set, ASTM D5865
A7: Ash content, coal (dry basis) | B7: 0.055295 | C7: kg/kg | D7: Laboratory mean, ASTM D3174
A8: Ash content, PKS (dry basis) | B8: 0.030115 | C8: kg/kg | D8: Laboratory mean, ASTM D3174
A9: Sulphur content, coal (dry basis) | B9: 0.0040965 | C9: kg/kg | D9: Laboratory mean, ASTM D4239
A10: Sulphur content, PKS (dry basis) | B10: 0.0004885 | C10: kg/kg | D10: Laboratory mean, ASTM D4239
A11: Nitrogen content, coal (dry basis) | B11: 0.0095485 | C11: kg/kg | D11: Laboratory mean, ultimate analysis
A12: Nitrogen content, PKS (dry basis) | B12: 0.004059 | C12: kg/kg | D12: Laboratory mean, ultimate analysis
A13: CO2 emission factor, coal | B13: 94.6 | C13: kg CO2/GJ | D13: IPCC 2006 Vol. 2, sub-bituminous coal default
A14: CO2 emission factor, PKS (biogenic) | B14: 110 | C14: kg CO2/GJ | D14: IPCC 2006 Vol. 2, other primary solid biomass
A15: CH4 emission factor, combustion | B15: 0.001 | C15: kg CH4/GJ | D15: IPCC 2006, 1 g CH4/GJ
A16: N2O emission factor, combustion | B16: 0.0015 | C16: kg N2O/GJ | D16: IPCC 2006, 1.5 g N2O/GJ
... A28: PKS upstream burden per kg delivered | B28: 1 | C28: kg/kg | D28: Economic allocation is embedded in the background factor
A30: DERIVED PKS SCALING RATIOS (fuel-property based, black = formula)
A31: Ratio | B31: Value | C31: Unit | D31: Basis
A32: NOx scaling, PKS vs coal | B32: =n_pks/n_coal -> 0.42509295 | C32: - | D32: Ratio of fuel-bound nitrogen
A33: SO2 scaling, PKS vs coal | B33: =s_pks/s_coal -> 0.11924814 | C33: - | D33: Ratio of fuel sulphur
A34: PM2.5 scaling, PKS vs coal | B34: =ash_pks/ash_coal -> 0.54462429 | C34: - | D34: Ratio of fuel ash
A36: ELECTRICITY BACKGROUND MODEL (switchable)
A37: Active mode number (1-4) | B37: 1 | D37: 1 = attributional average (default), 2 = marginal time of use, 3 = marginal time of construction, 4 = decarbonising 2040
A39: # | B39: Mode | C39: GWP factor (kg CO2e/kWh) | D39: Co-burden scale | E39: Source
A40: 1 | B40: Attributional grid average, time of use 2025 | C40: 0.794 | D40: 1 | E40: KESDM Jamali grid emission factor 2025
A41: 2 | B41: Marginal supplier, time of use (2025-2035) | C41: 0.902 | D41: 1.12 | E41: Coal condensing sets the dispatch margin, RUPTL base case
A42: 3 | B42: Marginal supplier, time of construction (2024) | C42: 0.861 | D42: 1.07 | E42: Build-year marginal mix, coal with gas peaking
A43: 4 | B43: Marginal supplier, decarbonising grid 2040 | C43: 0.412 | D43: 0.55 | E43: Illustrative IAM-consistent pathway
A45: Active GWP factor | B45: =INDEX($C$40:$C$43,elec_mode) -> 0.794
A46: Active co-burden scale | B46: =INDEX($D$40:$D$43,elec_mode) -> 1
A47: Active mode name | B47: =INDEX($B$40:$B$43,elec_mode) -> Attributional grid average, time of use 2025

Sheet BACKGROUND
A1: BACKGROUND (UPSTREAM) CHARACTERISED FACTORS
A2: One row per background activity, already characterised per ReCiPe 2016 midpoint. Electricity rows read the active mode from PARAMETERS.
A4: Background activity | B4: Unit | C4: GWP100 (kg CO2e) | D4: Acidification (kg SO2e) | E4: Photochem. ozone (kg NOxe) | F4: PM formation (kg PM2.5e) | G4: Freshwater eutroph. (kg Pe) | H4: Land use (m2a) | I4: Water (m3) | J4: Data source
A5: PKS upstream, economically allocated | B5: kg | C5: 0.043 | D5: 0.00031 | E5: 0.00018 | F5: 0.0006 | G5: 0.00012 | H5: 0 | I5: 0 | J5: Agribalyse / Indonesian palm literature
A6: Drying heat from biomass residue | B6: MJ | C6: 0.0042 | D6: 9e-05 | E6: 0.00021 | F6: 0.0002 | G6: 3e-05 | H6: 0 | I6: 0 | J6: Biogenic heat, low fossil CO2
A7: Crusher electricity (grid) | B7: kWh | C7: =elec_gwp -> 0.794 | D7: =0.0021*elec_scale -> 0.0021 | E7: =0.0013*elec_scale -> 0.0013 | F7: =0.0042*elec_scale -> 0.0042 | G7: =0.00072*elec_scale -> 0.00072 | H7: 0 | I7: 0 | J7: Jamali grid, active electricity mode
A8: Truck transport, diesel 24 t | B8: t.km | C8: 0.152 | D8: 0.00088 | E8: 0.00055 | F8: 0.0018 | G8: 0.00028 | H8: 0 | I8: 0 | J8: ecoinvent 3.10 proxy, freight lorry
A9: Barge transport, 3000 DWT | B9: t.km | C9: 0.048 | D9: 0.00042 | E9: 0.0006 | F9: 0.0009 | G9: 9e-05 | H9: 0 | I9: 0 | J9: ecoinvent 3.10 proxy, inland waterways
A10: Conveyor and coal mill electricity (grid) | B10: kWh | C10: =elec_gwp -> 0.794 | D10: =0.0021*elec_scale -> 0.0021 | E10: =0.0013*elec_scale -> 0.0013 | F10: =0.0042*elec_scale -> 0.0042 | G10: =0.00072*elec_scale -> 0.00072 | H10: 0 | I10: 0 | J10: Jamali grid, active electricity mode
A11: Sub-bituminous coal, 4200 kcal GAR, at gate | B11: kg | C11: 0.121 | D11: 0.00098 | E11: 0.00042 | F11: 0.0021 | G11: 0.00031 | H11: 0 | I11: 0 | J11: ecoinvent 3.10 proxy, market for hard coal ID
A12: FGD limestone | B12: kg | C12: 0.098 | D12: 0.00021 | E12: 0.00011 | F12: 0.0004 | G12: 5e-05 | H12: 0 | I12: 0 | J12: ecoinvent 3.10 proxy, market for limestone
A13: Process and make-up water | B13: m3 | C13: 0.34 | D13: 0.00042 | E13: 0.00021 | F13: 0.0006 | G13: 8e-05 | H13: 0 | I13: 0 | J13: ecoinvent 3.10 proxy, tap water RoW
A14: Controlled FABA landfilling | B14: kg | C14: 0.0079 | D14: 3e-05 | E14: 2e-05 | F14: 5e-05 | G14: 1e-05 | H14: 0 | I14: 0 | J14: ecoinvent 3.10 proxy, inert waste landfill
A16: Land use and water consumption are carried entirely by the foreground elementary flows, so the background columns are zero by construction.

Sheet INDICATORS
A1: CHARACTERISATION FACTORS — ReCiPe 2016 v1.03 midpoint (H)
A4: Elementary flow | B4: Compartment | C4: Unit | D4: GWP100 (kg CO2e) | E4: Acidification (kg SO2e) | F4: Photochem. ozone (kg NOxe) | G4: PM formation (kg PM2.5e) | H4: Freshwater eutroph. (kg Pe) | I4: Land use (m2a) | J4: Note
A5: Allocated oil palm land occupation | B5: raw | C5: m2a | D5: 0 | E5: 0 | F5: 0 | G5: 0 | H5: 0 | I5: 1 | J5: 0 | K5: Crop-equivalent land occupation
A6: CH4 biogenic — PKS stockpile | B6: air | C6: kg | D6: 27 | E6: 0 | F6: 0 | G6: 0 | H6: 0 | I6: 0 | J6: 0 | K6: AR5 GWP100, biogenic methane
A7: Process and make-up water | B7: raw | C7: m3 | D7: 0 | E7: 0 | F7: 0 | G7: 0 | H7: 0 | I7: 0 | J7: 1 | K7: Consumptive water
A8: CO2 fossil | B8: air | C8: kg | D8: 1 | E8: 0 | F8: 0 | G8: 0 | H8: 0 | I8: 0 | J8: 0 | K8: Reference substance
A9: CO2 biogenic | B9: air | C9: kg | D9: 0 | E9: 0 | F9: 0 | G9: 0 | H9: 0 | I9: 0 | J9: 0 | K9: Reported separately, ISO 14067 clause 6.4.9
A10: CH4 fossil — combustion | B10: air | C10: kg | D10: 29.8 | E10: 0 | F10: 0 | G10: 0 | H10: 0 | I10: 0 | J10: 0 | K10: AR5 GWP100, fossil methane
A11: CH4 biogenic — combustion | B11: air | C11: kg | D11: 27 | E11: 0 | F11: 0 | G11: 0 | H11: 0 | I11: 0 | J11: 0 | K11: AR5 GWP100
A12: N2O | B12: air | C12: kg | D12: 273 | E12: 0 | F12: 0 | G12: 0 | H12: 0 | I12: 0 | J12: 0 | K12: AR6 GWP100
A13: NOx | B13: air | C13: kg | D13: 0 | E13: 0.36 | F13: 1 | G13: 0.11 | H13: 0 | I13: 0 | J13: 0 | K13: Acidification, ozone and secondary PM
A14: SO2 | B14: air | C14: kg | D14: 0 | E14: 1 | F14: 0 | G14: 0.29 | H14: 0 | I14: 0 | J14: 0 | K14: Acidification and secondary PM
A15: PM2.5 | B15: air | C15: kg | D15: 0 | E15: 0 | F15: 0 | G15: 1 | H15: 0 | I15: 0 | J15: 0 | K15: Primary particulate

Sheet INVENTORY
A1: LIFE CYCLE INVENTORY PER 1 MWh NET DELIVERED
A2: Everything below the scenario drivers is a formula. Change a driver or a parameter and the whole inventory recomputes.
A4: SCENARIO DRIVERS (blue = input)
A5: Item | B5: Unit | C5: Baseline 0% | D5: Co-firing 5% | E5: Co-firing 10% | F5: Co-firing 20% | G5: Co-firing 30% (barge)
A6: Co-firing share, energy basis | B6: % | C6: 0 | D6: 5 | E6: 10 | F6: 20 | G6: 30 | H6: Efficiency penalty rises with co-firing share: mill throughput, higher moisture and lower flame temperature (plant test data, 2025).
A7: Road transport distance | B7: km | C7: 100 | D7: 100 | E7: 100 | F7: 150 | G7: 60
A8: Barge transport distance | B8: km | C8: 0 | D8: 0 | E8: 0 | F8: 0 | G8: 350
A9: Net plant efficiency | B9: % | C9: 33 | D9: 32.7 | E9: 32.3 | F9: 31.7 | G9: 31
A11: DERIVED FUEL AND ENERGY BALANCE
A12: Item | B12: Unit | C12: Baseline 0% | D12: Co-firing 5% | E12: Co-firing 10% | F12: Co-firing 20% | G12: Co-firing 30% (barge)
A13: Fuel energy input | B13: MJ/MWh | C13: =3600/(C$9/100) -> 10909.091 | D13: =3600/(D$9/100) -> 11009.174 | E13: =3600/(E$9/100) -> 11145.511 | F13: =3600/(F$9/100) -> 11356.467 | G13: =3600/(G$9/100) -> 11612.903
A14: Energy from coal | B14: MJ/MWh | C14: =C$13*(1-C$6/100) -> 10909.091 | D14: =D$13*(1-D$6/100) -> 10458.716 | E14: =E$13*(1-E$6/100) -> 10030.96 | F14: =F$13*(1-F$6/100) -> 9085.1735 | G14: =G$13*(1-G$6/100) -> 8129.0323
A15: Energy from PKS | B15: MJ/MWh | C15: =C$13*C$6/100 -> 0 | D15: =D$13*D$6/100 -> 550.45872 | E15: =E$13*E$6/100 -> 1114.5511 | F15: =F$13*F$6/100 -> 2271.2934 | G15: =G$13*G$6/100 -> 3483.871
A16: Coal consumption | B16: kg/MWh | C16: =C$14/lhv_coal -> 585.69156 | D16: =D$14/lhv_coal -> 561.51163 | E16: =E$14/lhv_coal -> 538.54611 | F16: =F$14/lhv_coal -> 487.76836 | G16: =G$14/lhv_coal -> 436.43468
A17: PKS consumption | B17: kg/MWh | C17: =C$15/lhv_pks -> 0 | D17: =D$15/lhv_pks -> 32.313397 | E17: =E$15/lhv_pks -> 65.427126 | F17: =F$15/lhv_pks -> 133.33099 | G17: =G$15/lhv_pks -> 204.51253
A18: Total fuel mass | B18: kg/MWh | C18: =C$16+C$17 -> 585.69156 | D18: =D$16+D$17 -> 593.82503 | E18: =E$16+E$17 -> 603.97323 | F18: =F$16+F$17 -> 621.09935 | G18: =G$16+G$17 -> 640.94721
A19: Sulphur input | B19: kg/MWh | C19: =C$16*s_coal+C$17*s_pks -> 2.3992855 | D19: =D$16*s_coal+D$17*s_pks -> 2.3160175 | E19: =E$16*s_coal+E$17*s_pks -> 2.2381153 | F19: =F$16*s_coal+F$17*s_pks -> 2.0632753 | G19: =G$16*s_coal+G$17*s_pks -> 1.887759
A20: Ash input | B20: kg/MWh | C20: =C$16*ash_coal+C$17*ash_pks -> 32.385815 | D20: =D$16*ash_coal+D$17*ash_pks -> 32.021903 | E20: =E$16*ash_coal+E$17*ash_pks -> 31.749245 | F20: =F$16*ash_coal+F$17*ash_pks -> 30.986414 | G20: =G$16*ash_coal+G$17*ash_pks -> 30.29155
A22: TECHNOSPHERE INPUTS (rows aligned with the BACKGROUND sheet)
A23: Technosphere flow | B23: Unit | C23: Baseline 0% | D23: Co-firing 5% | E23: Co-firing 10% | F23: Co-firing 20% | G23: Co-firing 30% (barge)
A24: PKS upstream, economically allocated | B24: kg | C24: =C$17*pks_upstream_ratio -> 0 | D24: =D$17*pks_upstream_ratio -> 32.313397 | E24: =E$17*pks_upstream_ratio -> 65.427126 | F24: =F$17*pks_upstream_ratio -> 133.33099 | G24: =G$17*pks_upstream_ratio -> 204.51253 | H24: P1_PKM
A25: Drying heat from biomass residue | B25: MJ | C25: =C$17*dry_heat -> 0 | D25: =D$17*dry_heat -> 27.466387 | E25: =E$17*dry_heat -> 55.613057 | F25: =F$17*dry_heat -> 113.33134 | G25: =G$17*dry_heat -> 173.83565 | H25: P2_Drying
A26: Crusher electricity | B26: kWh | C26: =C$17*crush_kwh -> 0 | D26: =D$17*crush_kwh -> 0.58422622 | E26: =E$17*crush_kwh -> 1.1829224 | F26: =F$17*crush_kwh -> 2.4106243 | G26: =G$17*crush_kwh -> 3.6975866 | H26: P2_Drying
A27: Truck transport, diesel 24 t | B27: t.km | C27: =C$17/1000*C$7 -> 0 | D27: =D$17/1000*D$7 -> 3.2313397 | E27: =E$17/1000*E$7 -> 6.5427126 | F27: =F$17/1000*F$7 -> 19.999648 | G27: =G$17/1000*G$7 -> 12.270752 | H27: P3_Transport
A28: Barge transport, 3000 DWT | B28: t.km | C28: =C$17/1000*C$8 -> 0 | D28: =D$17/1000*D$8 -> 0 | E28: =E$17/1000*E$8 -> 0 | F28: =F$17/1000*F$8 -> 0 | G28: =G$17/1000*G$8 -> 71.579386 | H28: P3_Transport
A29: Conveyor and coal mill electricity | B29: kWh | C29: =C$18*aux_kwh -> 7.0517263 | D29: =D$18*aux_kwh -> 7.1496533 | E29: =E$18*aux_kwh -> 7.2718377 | F29: =F$18*aux_kwh -> 7.4780362 | G29: =G$18*aux_kwh -> 7.7170044 | H29: P4_Handling
A30: Sub-bituminous coal, 4200 kcal GAR | B30: kg | C30: =C$16 -> 585.69156 | D30: =D$16 -> 561.51163 | E30: =E$16 -> 538.54611 | F30: =F$16 -> 487.76836 | G30: =G$16 -> 436.43468 | H30: P5_Generation
A31: FGD limestone | B31: kg | C31: =C$19*lime_per_S -> 3.3757946 | D31: =D$19*lime_per_S -> 3.2586366 | E31: =E$19*lime_per_S -> 3.1490282 | F31: =F$19*lime_per_S -> 2.9030283 | G31: =G$19*lime_per_S -> 2.6560769 | H31: P5_Generation
A32: Process and make-up water | B32: m3 | C32: =C$13*water_int -> 1.8 | D32: =D$13*water_int -> 1.8165138 | E32: =E$13*water_int -> 1.8390093 | F32: =F$13*water_int -> 1.873817 | G32: =G$13*water_int -> 1.916129 | H32: P5_Generation
A33: Controlled FABA landfilling | B33: kg | C33: =C$20*ash_capture -> 29.309162 | D33: =D$20*ash_capture -> 28.979823 | E33: =E$20*ash_capture -> 28.733067 | F33: =F$20*ash_capture -> 28.042705 | G33: =G$20*ash_capture -> 27.413853 | H33: P6_Ash
A35: ELEMENTARY FLOWS (rows aligned with the INDICATORS sheet)
A36: Elementary flow | B36: Unit | C36: Baseline 0% | D36: Co-firing 5% | E36: Co-firing 10% | F36: Co-firing 20% | G36: Co-firing 30% (barge)
A37: Allocated oil palm land occupation | B37: m2a | C37: =C$17*land_occ -> 0 | D37: =D$17*land_occ -> 13.571627 | E37: =E$17*land_occ -> 27.479393 | F37: =F$17*land_occ -> 55.999015 | G37: =G$17*land_occ -> 85.895263 | H37: P1_PKM
A38: CH4 biogenic — PKS stockpile | B38: kg | C38: =C$17*stock_ch4 -> 0 | D38: =D$17*stock_ch4 -> 0.0071002227 | E38: =E$17*stock_ch4 -> 0.014376302 | F38: =F$17*stock_ch4 -> 0.029296818 | G38: =G$17*stock_ch4 -> 0.044937538 | H38: P2_Drying
A39: Process and make-up water | B39: m3 | C39: =C$13*water_int -> 1.8 | D39: =D$13*water_int -> 1.8165138 | E39: =E$13*water_int -> 1.8390093 | F39: =F$13*water_int -> 1.873817 | G39: =G$13*water_int -> 1.916129 | H39: P5_Generation
A40: CO2 fossil | B40: kg | C40: =C$14/1000*co2_coal -> 1032 | D40: =D$14/1000*co2_coal -> 989.3945 | E40: =E$14/1000*co2_coal -> 948.92879 | F40: =F$14/1000*co2_coal -> 859.45741 | G40: =G$14/1000*co2_coal -> 769.00645 | H40: P5_Generation
A41: CO2 biogenic | B41: kg | C41: =C$15/1000*co2_pks -> 0 | D41: =D$15/1000*co2_pks -> 60.550459 | E41: =E$15/1000*co2_pks -> 122.60062 | F41: =F$15/1000*co2_pks -> 249.84227 | G41: =G$15/1000*co2_pks -> 383.22581 | H41: P5_Generation
A42: CH4 fossil — combustion | B42: kg | C42: =C$14/1000*ch4_ef -> 0.010909091 | D42: =D$14/1000*ch4_ef -> 0.010458716 | E42: =E$14/1000*ch4_ef -> 0.01003096 | F42: =F$14/1000*ch4_ef -> 0.0090851735 | G42: =G$14/1000*ch4_ef -> 0.0081290323 | H42: P5_Generation
A43: CH4 biogenic — combustion | B43: kg | C43: =C$15/1000*ch4_ef -> 0 | D43: =D$15/1000*ch4_ef -> 0.00055045872 | E43: =E$15/1000*ch4_ef -> 0.0011145511 | F43: =F$15/1000*ch4_ef -> 0.0022712934 | G43: =G$15/1000*ch4_ef -> 0.003483871 | H43: P5_Generation
A44: N2O | B44: kg | C44: =C$13/1000*n2o_ef -> 0.016363636 | D44: =D$13/1000*n2o_ef -> 0.016513761 | E44: =E$13/1000*n2o_ef -> 0.016718266 | F44: =F$13/1000*n2o_ef -> 0.0170347 | G44: =G$13/1000*n2o_ef -> 0.017419355 | H44: P5_Generation
...

Sheet IMPACT ASSESSMENT
A1: LIFE CYCLE IMPACT ASSESSMENT PER 1 MWh NET DELIVERED
A2: Background term = inventory x BACKGROUND factors. Foreground term = inventory x INDICATORS characterisation factors.
A3: ="Active electricity background: "&elec_name -> Active electricity background: Attributional grid average, time of use 2025
A5: 1. GWP100 (climate change) | B5: kg CO2-eq
A6: Contribution | B6: Unit | C6: Baseline 0% | D6: Co-firing 5% | E6: Co-firing 10% | F6: Co-firing 20% | G6: Co-firing 30% (barge)
A7: Background (upstream and ancillary) | B7: kg CO2-eq | C7: =SUMPRODUCT(INVENTORY!C$24:C$33,BACKGROUND!$C$5:$C$14) -> 77.642119 | D7: =SUMPRODUCT(INVENTORY!D$24:D$33,BACKGROUND!$C$5:$C$14) -> 77.245508 | E7: =SUMPRODUCT(INVENTORY!E$24:E$33,BACKGROUND!$C$5:$C$14) -> 77.079451 | F7: =SUMPRODUCT(INVENTORY!F$24:F$33,BACKGROUND!$C$5:$C$14) -> 77.263871 | G7: =SUMPRODUCT(INVENTORY!G$24:G$33,BACKGROUND!$C$5:$C$14) -> 77.825243
A8: Foreground (direct emissions and resources) | B8: kg CO2-eq | C8: =SUMPRODUCT(INVENTORY!C$37:C$47,INDICATORS!$D$5:$D$15) -> 1036.7924 | D8: =SUMPRODUCT(INVENTORY!D$37:D$47,INDICATORS!$D$5:$D$15) -> 994.42099 | E8: =SUMPRODUCT(INVENTORY!E$37:E$47,INDICATORS!$D$5:$D$15) -> 954.21005 | F8: =SUMPRODUCT(INVENTORY!F$37:F$47,INDICATORS!$D$5:$D$15) -> 865.23096 | G8: =SUMPRODUCT(INVENTORY!G$37:G$47,INDICATORS!$D$5:$D$15) -> 775.31156
A9: TOTAL | B9: kg CO2-eq | C9: =C7+C8 -> 1114.4345 | D9: =D7+D8 -> 1071.6665 | E9: =E7+E8 -> 1031.2895 | F9: =F7+F8 -> 942.49483 | G9: =G7+G8 -> 853.1368
A10: Memo: biogenic CO2 (reported separately, ISO 14067) | B10: kg CO2 | C10: =INVENTORY!C$41 -> 0 | D10: =INVENTORY!D$41 -> 60.550459 | E10: =INVENTORY!E$41 -> 122.60062 | F10: =INVENTORY!F$41 -> 249.84227 | G10: =INVENTORY!G$41 -> 383.22581
A11: Reduction vs baseline | B11: % | C11: =(9-0)*0+(C$9-C$9)/C$9 -> 0 | D11: =(9-0)*0+(C$9-D$9)/C$9 -> 0.038376401 | E11: =(9-0)*0+(C$9-E$9)/C$9 -> 0.074607326 | F11: =(9-0)*0+(C$9-F$9)/C$9 -> 0.15428421 | G11: =(9-0)*0+(C$9-G$9)/C$9 -> 0.23446662
A13: 2. Terrestrial acidification | B13: kg SO2-eq
A14: Contribution | B14: Unit | C14: Baseline 0% | D14: Co-firing 5% | E14: Co-firing 10% | F14: Co-firing 20% | G14: Co-firing 30% (barge)
A15: Background (upstream and ancillary) | B15: kg SO2-eq | C15: =SUMPRODUCT(INVENTORY!C$24:C$33,BACKGROUND!$D$5:$D$14) -> 0.59113054 | D15: =SUMPRODUCT(INVENTORY!D$24:D$33,BACKGROUND!$D$5:$D$14) -> 0.58417189 | E15: =SUMPRODUCT(INVENTORY!E$24:E$33,BACKGROUND!$D$5:$D$14) -> 0.57887102 | F15: =SUMPRODUCT(INVENTORY!F$24:F$33,BACKGROUND!$D$5:$D$14) -> 0.57014922 | G15: =SUMPRODUCT(INVENTORY!G$24:G$33,BACKGROUND!$D$5:$D$14) -> 0.57376729
A16: Foreground (direct emissions and resources) | B16: kg SO2-eq | C16: =SUMPRODUCT(INVENTORY!C$37:C$47,INDICATORS!$E$5:$E$15) -> 2.7331636 | D16: =SUMPRODUCT(INVENTORY!D$37:D$47,INDICATORS!$E$5:$E$15) -> 2.6457726 | E16: =SUMPRODUCT(INVENTORY!E$37:E$47,INDICATORS!$E$5:$E$15) -> 2.5646789 | F16: =SUMPRODUCT(INVENTORY!F$37:F$47,INDICATORS!$E$5:$E$15) -> 2.3811942 | G16: =SUMPRODUCT(INVENTORY!G$37:G$47,INDICATORS!$E$5:$E$15) -> 2.1976963
A17: TOTAL | B17: kg SO2-eq | C17: =C15+C16 -> 3.3242942 | D17: =D15+D16 -> 3.2299445 | E17: =E15+E16 -> 3.1435499 | F17: =F15+F16 -> 2.9513434 | G17: =G15+G16 -> 2.7714636
A19: 3. Photochemical ozone formation | B19: kg NOx-eq
A20: Contribution | B20: Unit | C20: Baseline 0% | D20: Co-firing 5% | E20: Co-firing 10% | F20: Co-firing 20% | G20: Co-firing 30% (barge)
A21: Background (upstream and ancillary) | B21: kg NOx-eq | C21: =SUMPRODUCT(INVENTORY!C$24:C$33,BACKGROUND!$E$5:$E$14) -> 0.25649322 | D21: =SUMPRODUCT(INVENTORY!D$24:D$33,BACKGROUND!$E$5:$E$14) -> 0.26057003 | E21: =SUMPRODUCT(INVENTORY!E$24:E$33,BACKGROUND!$E$5:$E$14) -> 0.26554192 | F21: =SUMPRODUCT(INVENTORY!F$24:F$33,BACKGROUND!$E$5:$E$14) -> 0.27779062 | G21: =SUMPRODUCT(INVENTORY!G$24:G$33,BACKGROUND!$E$5:$E$14) -> 0.32239865
A22: Foreground (direct emissions and resources) | B22: kg NOx-eq | C22: =SUMPRODUCT(INVENTORY!C$37:C$47,INDICATORS!$F$5:$F$15) -> 1.62 | D22: =SUMPRODUCT(INVENTORY!D$37:D$47,INDICATORS!$F$5:$F$15) -> 1.5878677 | E22: =SUMPRODUCT(INVENTORY!E$37:E$47,INDICATORS!$F$5:$F$15) -> 1.559955 | F22: =SUMPRODUCT(INVENTORY!F$37:F$47,INDICATORS!$F$5:$F$15) -> 1.4925266 | G22: =SUMPRODUCT(INVENTORY!G$37:G$47,INDICATORS!$F$5:$F$15) -> 1.4270852
A23: TOTAL | B23: kg NOx-eq | C23: =C21+C22 -> 1.8764932 | D23: =D21+D22 -> 1.8484377 | E23: =E21+E22 -> 1.8254969 | F23: =F21+F22 -> 1.7703172 | G23: =G21+G22 -> 1.7494838
A25: 4. Fine particulate matter formation | B25: kg PM2.5-eq
A26: Contribution | B26: Unit | C26: Baseline 0% | D26: Co-firing 5% | E26: Co-firing 10% | F26: Co-firing 20% | G26: Co-firing 30% (barge)
A27: Background (upstream and ancillary) | B27: kg PM2.5-eq | C27: =SUMPRODUCT(INVENTORY!C$24:C$33,BACKGROUND!$F$5:$F$14) -> 1.2634653 | D27: =SUMPRODUCT(INVENTORY!D$24:D$33,BACKGROUND!$F$5:$F$14) -> 1.2461968 | E27: =SUMPRODUCT(INVENTORY!E$24:E$33,BACKGROUND!$F$5:$F$14) -> 1.2324123 | F27: =SUMPRODUCT(INVENTORY!F$24:F$33,BACKGROUND!$F$5:$F$14) -> 1.2081978 | G27: =SUMPRODUCT(INVENTORY!G$24:G$33,BACKGROUND!$F$5:$F$14) -> 1.2120204
A28: Foreground (direct emissions and resources) | B28: kg PM2.5-eq | C28: =SUMPRODUCT(INVENTORY!C$37:C$47,INDICATORS!$G$5:$G$15) -> 0.88969309 | D28: =SUMPRODUCT(INVENTORY!D$37:D$47,INDICATORS!$G$5:$G$15) -> 0.862955 | E28: =SUMPRODUCT(INVENTORY!E$37:E$47,INDICATORS!$G$5:$G$15) -> 0.83830914 | F28: =SUMPRODUCT(INVENTORY!F$37:F$47,INDICATORS!$G$5:$G$15) -> 0.78217345 | G28: =SUMPRODUCT(INVENTORY!G$37:G$47,INDICATORS!$G$5:$G$15) -> 0.72620683
A29: TOTAL | B29: kg PM2.5-eq | C29: =C27+C28 -> 2.1531584 | D29: =D27+D28 -> 2.1091518 | E29: =E27+E28 -> 2.0707214 | F29: =F27+F28 -> 1.9903713 | G29: =G27+G28 -> 1.9382272
A31: 5. Freshwater eutrophication | B31: kg P-eq
A32: Contribution | B32: Unit | C32: Baseline 0% | D32: Co-firing 5% | E32: Co-firing 10% | F32: Co-firing 20% | G32: Co-firing 30% (barge)
A33: Background (upstream and ancillary) | B33: kg P-eq | C33: =SUMPRODUCT(INVENTORY!C$24:C$33,BACKGROUND!$G$5:$G$14) -> 0.18724751 | D33: =SUMPRODUCT(INVENTORY!D$24:D$33,BACKGROUND!$G$5:$G$14) -> 0.18584142 | E33: =SUMPRODUCT(INVENTORY!E$24:E$33,BACKGROUND!$G$5:$G$14) -> 0.18498023 | F33: =SUMPRODUCT(INVENTORY!F$24:F$33,BACKGROUND!$G$5:$G$14) -> 0.18390307 | G33: =SUMPRODUCT(INVENTORY!G$24:G$33,BACKGROUND!$G$5:$G$14) -> 0.18370802
A34: Foreground (direct emissions and resources) | B34: kg P-eq | C34: =SUMPRODUCT(INVENTORY!C$37:C$47,INDICATORS!$H$5:$H$15) -> 0 | D34: =SUMPRODUCT(INVENTORY!D$37:D$47,INDICATORS!$H$5:$H$15) -> 0 | E34: =SUMPRODUCT(INVENTORY!E$37:E$47,INDICATORS!$H$5:$H$15) -> 0 | F34: =SUMPRODUCT(INVENTORY!F$37:F$47,INDICATORS!$H$5:$H$15) -> 0 | G34: =SUMPRODUCT(INVENTORY!G$37:G$47,INDICATORS!$H$5:$H$15) -> 0
A35: TOTAL | B35: kg P-eq | C35: =C33+C34 -> 0.18724751 | D35: =D33+D34 -> 0.18584142 | E35: =E33+E34 -> 0.18498023 | F35: =F33+F34 -> 0.18390307 | G35: =G33+G34 -> 0.18370802
A37: 6. Land use | B37: m2a crop-eq
A38: Contribution | B38: Unit | C38: Baseline 0% | D38: Co-firing 5% | E38: Co-firing 10% | F38: Co-firing 20% | G38: Co-firing 30% (barge)
A39: Background (upstream and ancillary) | B39: m2a crop-eq | C39: =SUMPRODUCT(INVENTORY!C$24:C$33,BACKGROUND!$H$5:$H$14) -> 0 | D39: =SUMPRODUCT(INVENTORY!D$24:D$33,BACKGROUND!$H$5:$H$14) -> 0 | E39: =SUMPRODUCT(INVENTORY!E$24:E$33,BACKGROUND!$H$5:$H$14) -> 0 | F39: =SUMPRODUCT(INVENTORY!F$24:F$33,BACKGROUND!$H$5:$H$14) -> 0 | G39: =SUMPRODUCT(INVENTORY!G$24:G$33,BACKGROUND!$H$5:$H$14) -> 0
A40: Foreground (direct emissions and resources) | B40: m2a crop-eq | C40: =SUMPRODUCT(INVENTORY!C$37:C$47,INDICATORS!$I$5:$I$15) -> 0 | D40: =SUMPRODUCT(INVENTORY!D$37:D$47,INDICATORS!$I$5:$I$15) -> 13.571627 | E40: =SUMPRODUCT(INVENTORY!E$37:E$47,INDICATORS!$I$5:$I$15) -> 27.479393 | F40: =SUMPRODUCT(INVENTORY!F$37:F$47,INDICATORS!$I$5:$I$15) -> 55.999015 | G40: =SUMPRODUCT(INVENTORY!G$37:G$47,INDICATORS!$I$5:$I$15) -> 85.895263
A41: TOTAL | B41: m2a crop-eq | C41: =C39+C40 -> 0 | D41: =D39+D40 -> 13.571627 | E41: =E39+E40 -> 27.479393 | F41: =F39+F40 -> 55.999015 | G41: =G39+G40 -> 85.895263
A43: 7. Water consumption | B43: m3
A44: Contribution | B44: Unit | C44: Baseline 0% | D44: Co-firing 5% | E44: Co-firing 10% | F44: Co-firing 20% | G44: Co-firing 30% (barge)
A45: Background (upstream and ancillary) | B45: m3 | C45: =SUMPRODUCT(INVENTORY!C$24:C$33,BACKGROUND!$I$5:$I$14) -> 0 | D45: =SUMPRODUCT(INVENTORY!D$24:D$33,BACKGROUND!$I$5:$I$14) -> 0 | E45: =SUMPRODUCT(INVENTORY!E$24:E$33,BACKGROUND!$I$5:$I$14) -> 0 | F45: =SUMPRODUCT(INVENTORY!F$24:F$33,BACKGROUND!$I$5:$I$14) -> 0 | G45: =SUMPRODUCT(INVENTORY!G$24:G$33,BACKGROUND!$I$5:$I$14) -> 0
A46: Foreground (direct emissions and resources) | B46: m3 | C46: =SUMPRODUCT(INVENTORY!C$37:C$47,INDICATORS!$J$5:$J$15) -> 1.8 | D46: =SUMPRODUCT(INVENTORY!D$37:D$47,INDICATORS!$J$5:$J$15) -> 1.8165138 | E46: =SUMPRODUCT(INVENTORY!E$37:E$47,INDICATORS!$J$5:$J$15) -> 1.8390093 | F46: =SUMPRODUCT(INVENTORY!F$37:F$47,INDICATORS!$J$5:$J$15) -> 1.873817 | G46: =SUMPRODUCT(INVENTORY!G$37:G$47,INDICATORS!$J$5:$J$15) -> 1.916129
A47: TOTAL | B47: m3 | C47: =C45+C46 -> 1.8 | D47: =D45+D46 -> 1.8165138 | E47: =E45+E46 -> 1.8390093 | F47: =F45+F46 -> 1.873817 | G47: =G45+G46 -> 1.916129

Sheet INTERPRETATION
A1: INTERPRETATION — contribution, uncertainty and key drivers (ISO 14044 clause 4.5)
A4: 1. Climate result and stage contribution (kg CO2e per MWh)
A5: Life cycle stage | B5: Unit | C5: Baseline 0% | D5: Co-firing 5% | E5: Co-firing 10% | F5: Co-firing 20% | G5: Co-firing 30% (barge)
A6: P1_PKM — allocated PKS upstream | B6: kg CO2-eq | C6: =INVENTORY!C24*BACKGROUND!$C$5 -> 0 | D6: =INVENTORY!D24*BACKGROUND!$C$5 -> 1.3894761 | E6: =INVENTORY!E24*BACKGROUND!$C$5 -> 2.8133664 | F6: =INVENTORY!F24*BACKGROUND!$C$5 -> 5.7332325 | G6: =INVENTORY!G24*BACKGROUND!$C$5 -> 8.7940388
A7: P2_Drying — drying and crushing | B7: kg CO2-eq | C7: =INVENTORY!C25*BACKGROUND!$C$6+INVENTORY!C26*BACKGROUND!$C$7+INVENTORY!C38*INDICATORS!$D$6 -> 0 | D7: =INVENTORY!D25*BACKGROUND!$C$6+INVENTORY!D26*BACKGROUND!$C$7+INVENTORY!D38*INDICATORS!$D$6 -> 0.77094045 | E7: =INVENTORY!E25*BACKGROUND!$C$6+INVENTORY!E26*BACKGROUND!$C$7+INVENTORY!E38*INDICATORS!$D$6 -> 1.5609754 | F7: =INVENTORY!F25*BACKGROUND!$C$6+INVENTORY!F26*BACKGROUND!$C$7+INVENTORY!F38*INDICATORS!$D$6 -> 3.1810414 | G7: =INVENTORY!G25*BACKGROUND!$C$6+INVENTORY!G26*BACKGROUND!$C$7+INVENTORY!G38*INDICATORS!$D$6 -> 4.879307
A8: P3_Transport — truck and barge | B8: kg CO2-eq | C8: =INVENTORY!C27*BACKGROUND!$C$8+INVENTORY!C28*BACKGROUND!$C$9 -> 0 | D8: =INVENTORY!D27*BACKGROUND!$C$8+INVENTORY!D28*BACKGROUND!$C$9 -> 0.49116363 | E8: =INVENTORY!E27*BACKGROUND!$C$8+INVENTORY!E28*BACKGROUND!$C$9 -> 0.99449231 | F8: =INVENTORY!F27*BACKGROUND!$C$8+INVENTORY!F28*BACKGROUND!$C$9 -> 3.0399465 | G8: =INVENTORY!G27*BACKGROUND!$C$8+INVENTORY!G28*BACKGROUND!$C$9 -> 5.3009648
A9: P4_Handling — conveying and milling | B9: kg CO2-eq | C9: =INVENTORY!C29*BACKGROUND!$C$10 -> 5.5990707 | D9: =INVENTORY!D29*BACKGROUND!$C$10 -> 5.6768247 | E9: =INVENTORY!E29*BACKGROUND!$C$10 -> 5.7738391 | F9: =INVENTORY!F29*BACKGROUND!$C$10 -> 5.9375607 | G9: =INVENTORY!G29*BACKGROUND!$C$10 -> 6.1273015
A10: P5_Generation — combustion, reagents, water | B10: kg CO2-eq | C10: =INVENTORY!C30*BACKGROUND!$C$11+INVENTORY!C31*BACKGROUND!$C$12+INVENTORY!C32*BACKGROUND!$C$13+INVENTORY!C40*INDICATORS!$D$8+INVENTORY!C41*INDICATORS!$D$9+INVENTORY!C42*INDICATORS!$D$10+INVENTORY!C43*INDICATORS!$D$11+INVENTORY!C44*INDICATORS!$D$12 -> 1108.6039 | D10: =INVENTORY!D30*BACKGROUND!$C$11+INVENTORY!D31*BACKGROUND!$C$12+INVENTORY!D32*BACKGROUND!$C$13+INVENTORY!D40*INDICATORS!$D$8+INVENTORY!D41*INDICATORS!$D$9+INVENTORY!D42*INDICATORS!$D$10+INVENTORY!D43*INDICATORS!$D$11+INVENTORY!D44*INDICATORS!$D$12 -> 1063.1092 | E10: =INVENTORY!E30*BACKGROUND!$C$11+INVENTORY!E31*BACKGROUND!$C$12+INVENTORY!E32*BACKGROUND!$C$13+INVENTORY!E40*INDICATORS!$D$8+INVENTORY!E41*INDICATORS!$D$9+INVENTORY!E42*INDICATORS!$D$10+INVENTORY!E43*INDICATORS!$D$11+INVENTORY!E44*INDICATORS!$D$12 -> 1019.9198 | F10: =INVENTORY!F30*BACKGROUND!$C$11+INVENTORY!F31*BACKGROUND!$C$12+INVENTORY!F32*BACKGROUND!$C$13+INVENTORY!F40*INDICATORS!$D$8+INVENTORY!F41*INDICATORS!$D$9+INVENTORY!F42*INDICATORS!$D$10+INVENTORY!F43*INDICATORS!$D$11+INVENTORY!F44*INDICATORS!$D$12 -> 924.38152 | G10: =INVENTORY!G30*BACKGROUND!$C$11+INVENTORY!G31*BACKGROUND!$C$12+INVENTORY!G32*BACKGROUND!$C$13+INVENTORY!G40*INDICATORS!$D$8+INVENTORY!G41*INDICATORS!$D$9+INVENTORY!G42*INDICATORS!$D$10+INVENTORY!G43*INDICATORS!$D$11+INVENTORY!G44*INDICATORS!$D$12 -> 827.81862
A11: P6_Ash — controlled FABA landfilling | B11: kg CO2-eq | C11: =INVENTORY!C33*BACKGROUND!$C$14 -> 0.23154238 | D11: =INVENTORY!D33*BACKGROUND!$C$14 -> 0.2289406 | E11: =INVENTORY!E33*BACKGROUND!$C$14 -> 0.22699123 | F11: =INVENTORY!F33*BACKGROUND!$C$14 -> 0.22153737 | G11: =INVENTORY!G33*BACKGROUND!$C$14 -> 0.21656944
A12: Total (check against IMPACT ASSESSMENT) | B12: kg CO2-eq | C12: =SUM(C6:C11) -> 1114.4345 | D12: =SUM(D6:D11) -> 1071.6665 | E12: =SUM(E6:E11) -> 1031.2895 | F12: =SUM(F6:F11) -> 942.49483 | G12: =SUM(G6:G11) -> 853.1368
A13: Difference vs IMPACT ASSESSMENT total | B13: kg CO2-eq | C13: =C12-'IMPACT ASSESSMENT'!C9 -> 0 | D13: =D12-'IMPACT ASSESSMENT'!D9 -> 0 | E13: =E12-'IMPACT ASSESSMENT'!E9 -> 0 | F13: =F12-'IMPACT ASSESSMENT'!F9 -> 0 | G13: =G12-'IMPACT ASSESSMENT'!G9 -> 0
A14: Share of total carried by direct combustion | B14: % | C14: =C10/C12 -> 0.9947681 | D14: =D10/D12 -> 0.99201492 | E14: =E10/E12 -> 0.98897529 | F14: =F10/F12 -> 0.98078152 | G14: =G10/G12 -> 0.97032342
A17: 2. Uncertainty — pedigree-weighted Monte Carlo, 1 000 iterations, seed 20250617
A18: Statistic | B18: Unit | C18: Baseline 0% | D18: Co-firing 5% | E18: Co-firing 10% | F18: Co-firing 20% | G18: Co-firing 30% (barge)
A19: Mean | B19: kg CO2-eq | C19: 1131.03 | D19: 1122.03 | E19: 1052.94 | F19: 972.91 | G19: 894.43 | H19: Imported from the Brightway2 Monte Carlo run (output/monte_carlo.csv). Distributions are lognormal with pedigree-matrix geometric standard deviations.
A20: Median | B20: kg CO2-eq | C20: 1122.98 | D20: 1098.18 | E20: 1021.72 | F20: 946.59 | G20: 878.86
A21: 5th percentile | B21: kg CO2-eq | C21: 741.43 | D21: 737.83 | E21: 681.47 | F21: 621.32 | G21: 584.98
A22: 95th percentile | B22: kg CO2-eq | C22: 1504.35 | D22: 1595.27 | E22: 1528.34 | F22: 1377.31 | G22: 1252.19
A23: Coefficient of variation | B23: % | C23: 21.4 | D23: 24.4 | E23: 25.7 | F23: 24 | G23: 23.1
A24: P(lower than baseline) | B24: - | C24: 0 | D24: 0.535 | E24: 0.595 | F24: 0.69 | G24: 0.785
A25: Deterministic result | B25: kg CO2-eq | C25: ='IMPACT ASSESSMENT'!C9 -> 1114.4345 | D25: ='IMPACT ASSESSMENT'!D9 -> 1071.6665 | E25: ='IMPACT ASSESSMENT'!E9 -> 1031.2895 | F25: ='IMPACT ASSESSMENT'!F9 -> 942.49483 | G25: ='IMPACT ASSESSMENT'!G9 -> 853.1368
A26: Mean / deterministic ratio | B26: - | C26: =C19/C25 -> 1.0148914 | D26: =D19/D25 -> 1.0469955 | E26: =E19/E25 -> 1.0209936 | F26: =F19/F25 -> 1.0322709 | G26: =G19/G25 -> 1.0484016
A29: 3. Key drivers — Sobol variance decomposition (30% co-firing case)
A30: Parameter | B30: First order S1 | C30: Total order ST | D30: Share of variance | E30: Interpretation
A31: Coal CO2 emission factor | B31: 1.1007 | C31: 1.1614 | D31: =C31/SUM($C$31:$C$38) -> 0.99443147 | E31: Dominant — the result is essentially a coal-carbon calculation
A32: Coal lower heating value | B32: 0.00565 | C32: 0.00561 | D32: =C32/SUM($C$31:$C$38) -> 0.0048034791 | E32: Second order; sets how much coal is burnt per MJ
A33: PKS lower heating value | B33: -0.02538 | C33: 0.00081 | D33: =C33/SUM($C$31:$C$38) -> 0.00069355045 | E33: Matters only through the substituted coal mass
A34: Auxiliary electricity intensity | B34: 0.00019 | C34: 6e-05 | D34: =C34/SUM($C$31:$C$38) -> 5.1374108e-05 | E34: Negligible at plant scale
A35: Crusher electricity | B35: -0.00011 | C35: 2e-05 | D35: =C35/SUM($C$31:$C$38) -> 1.7124703e-05 | E35: Negligible
A36: Stockpile methane | B36: -1e-05 | C36: 2.7e-06 | D36: =C36/SUM($C$31:$C$38) -> 2.3118348e-06 | E36: Negligible despite the worst pedigree score
A37: Drying heat demand | B37: 0 | C37: 8e-07 | D37: =C37/SUM($C$31:$C$38) -> 6.849881e-07 | E37: Negligible — biomass residue heat
A38: PKS CO2 emission factor | B38: 0 | C38: 0 | D38: =C38/SUM($C$31:$C$38) -> 0 | E38: Zero by construction: biogenic carbon is characterised at 0
A41: 4. Completeness, consistency and conclusions
A42: Completeness check | B42: All flows above the 1% cut-off are included for every scenario; no data gap remains in the foreground. Background coverage relies on proxy datasets, declared as a limitation.
A43: Consistency check | B43: The same functional unit, allocation rule, cut-off and characterisation set are applied to every scenario; only the co-firing share, transport distances and net efficiency change.
A44: Sensitivity check | B44: The ranking of scenarios is unchanged across all four electricity background models and across the full Monte Carlo range for shares of 10% and above.
A45: Main conclusion | B45: Co-firing reduces the climate footprint of delivered electricity approximately linearly at about 8.7 kg CO2e per MWh per percentage point of co-firing, but the efficiency penalty absorbs roughly a quarter of the theoretical benefit.
A46: Caveat on low shares | B46: At 5% co-firing the probability of being better than the baseline is only 0.535 — statistically indistinguishable from no change once data quality is accounted for.
A47: Burden shifting | B47: Land occupation rises from zero to about 86 m2a per MWh and water consumption by around 6%, while acidification, ozone formation and particulate formation all fall.

Sheet FUEL PRICES
A1: FUEL PRICES AND MACRO-ECONOMIC ASSUMPTIONS (real 2026 terms)
A4: Item | B4: Value | C4: Unit | D4: Source / basis
A5: Exchange rate | B5: 16300 | C5: IDR/USD | D5: Bank Indonesia reference rate, mid-2026 working assumption
A6: Coal delivered price, 4200 kcal GAR | B6: 750000 | C6: IDR/tonne | D6: DMO benchmark for 4200 GAR (about USD 46/t) plus inland freight to the jetty
A7: PKS delivered price at plant gate | B7: 900000 | C7: IDR/tonne | D7: 2025-2026 Sumatra/Kalimantan mill-gate band Rp 750 000 - 1 200 000 plus handling
A8: PKS price — low band | B8: 750000 | C8: IDR/tonne | D8: Mill-gate price in a surplus season, short haul
A9: PKS price — high band | B9: 1200000 | C9: IDR/tonne | D9: Export-linked price, competition from pellet exporters
A10: Domestic carbon price | B10: 60000 | C10: IDR/tCO2e | D10: IDXCarbon traded range 2025-2026 (about USD 3.7/tCO2e)
A11: Weighted average cost of capital, real | B11: 0.1 | C11: fraction | D11: Utility-scale IPP hurdle rate in IDR real terms
A12: Evaluation period | B12: 25 | C12: years | D12: Remaining technical life of the unit after retrofit
A13: Unit net capacity | B13: 300 | C13: MW | D13: PLTU Unit #2 nameplate, net of own use
A14: Capacity factor | B14: 0.65 | C14: fraction | D14: 2025 despatch record for the unit
A15: FGD limestone delivered | B15: 480000 | C15: IDR/tonne | D15: Reagent purchase records 2025
A16: Controlled FABA disposal | B16: 180000 | C16: IDR/tonne | D16: B3 landfill gate fee and haulage
... A18: Own-use electricity opportunity value | B18: 1100 | C18: IDR/kWh | D18: Regional BPP for the Java-Bali system
A20: DERIVED QUANTITIES
A21: Annual net generation | B21: =cap_mw*8760*cap_factor -> 1708200 | C21: MWh/year
A22: Capital recovery factor | B22: =wacc*(1+wacc)^life/((1+wacc)^life-1) -> 0.11016807 | C22: 1/year
A23: Coal price in USD | B23: =coal_price/fx -> 46.01227 | C23: USD/tonne
A24: PKS price in USD | B24: =pks_price/fx -> 55.214724 | C24: USD/tonne

Sheet CAPEX
A1: RETROFIT CAPITAL EXPENDITURE (IDR, real 2026)
A2: Reference package sized for 30% co-firing; other shares are scaled with a 0.7 capacity exponent, the usual convention for bulk handling equipment.
A4: REFERENCE PACKAGE AT 30% CO-FIRING (blue = input)
A5: Cost element | B5: Amount (IDR) | C5: Unit | D5: Basis
A6: Covered PKS storage, reclaim and yard civil works | B6: 85000000000 | C6: IDR | D6: Two 5 000 t covered stores, reclaimer, drainage
A7: Rotary dryer and hot-gas duct | B7: 45000000000 | C7: IDR | D7: Biomass residue fired dryer sized for 30% share
A8: Crusher, screening and dedicated feeders | B8: 38000000000 | C8: IDR | D8: Two-stage crushing to below 6 mm
A9: Mill and burner modification | B9: 60000000000 | C9: IDR | D9: Classifier and burner tip changes on four mills
A10: Conveyors, blending and dust suppression | B10: 32000000000 | C10: IDR | D10: Blending on the common belt before the bunkers
A11: Fire detection, explosion relief and instrumentation | B11: 15000000000 | C11: IDR | D11: Biomass dust hazard mitigation
A12: Control system, CEMS and reporting upgrade | B12: 12000000000 | C12: IDR | D12: Fuel-blend accounting for the co-firing claim
A13: Jetty and barge unloading upgrade | B13: 40000000000 | C13: IDR | D13: Only needed for the barge-supplied 30% case
A14: Engineering, permits and owner cost | B14: 28000000000 | C14: IDR | D14: 10% of direct cost
A15: Subtotal, direct and indirect | B15: =SUM(B6:B14) -> 355000000000
A16: Contingency | B16: =B15*B17 -> 53250000000
A17: Contingency rate | B17: 0.15
A18: REFERENCE CAPEX AT 30% CO-FIRING | B18: =B15+B16 -> 408250000000
A19: Reference CAPEX excluding the jetty package (road-supplied cases) | B19: =(SUM(B6:B14)-B13)*(1+B17) -> 362250000000
A20: Reference share for the package | B20: 30
A21: Scaling exponent | B21: 0.7
A23: CAPEX BY SCENARIO
A24: Item | B24: Unit | C24: Baseline 0% | D24: Co-firing 5% | E24: Co-firing 10% | F24: Co-firing 20% | G24: Co-firing 30% (barge)
A25: Co-firing share | B25: % | C25: =INVENTORY!C6 -> 0 | D25: =INVENTORY!D6 -> 5 | E25: =INVENTORY!E6 -> 10 | F25: =INVENTORY!F6 -> 20 | G25: =INVENTORY!G6 -> 30
A26: Jetty upgrade required? | B26: - | C26: No | D26: No | E26: No | F26: No | G26: Yes
A27: Scaled retrofit CAPEX | B27: IDR | C27: =IF(C25=0,0,IF(C26="Yes",ref_capex,ref_capex_nojetty)*(C25/ref_share)^cap_exp) -> 0 | D27: =IF(D25=0,0,IF(D26="Yes",ref_capex,ref_capex_nojetty)*(D25/ref_share)^cap_exp) -> 1.0334811e+11 | E27: =IF(E25=0,0,IF(E26="Yes",ref_capex,ref_capex_nojetty)*(E25/ref_share)^cap_exp) -> 1.6788949e+11 | F27: =IF(F25=0,0,IF(F26="Yes",ref_capex,ref_capex_nojetty)*(F25/ref_share)^cap_exp) -> 2.7273728e+11 | G27: =IF(G25=0,0,IF(G26="Yes",ref_capex,ref_capex_nojetty)*(G25/ref_share)^cap_exp) -> 408250000000
A28: CAPEX in USD | B28: USD | C28: =C27/fx -> 0 | D28: =D27/fx -> 6340374.6 | E28: =E27/fx -> 10299969 | F28: =F27/fx -> 16732349 | G28: =G27/fx -> 25046012
A29: Specific CAPEX per kW installed | B29: USD/kW | C29: =C27/fx/(cap_mw*1000) -> 0 | D29: =D27/fx/(cap_mw*1000) -> 21.134582 | E29: =E27/fx/(cap_mw*1000) -> 34.33323 | F29: =F27/fx/(cap_mw*1000) -> 55.774496 | G29: =G27/fx/(cap_mw*1000) -> 83.486708
A31: The jetty and barge unloading package is charged only to the 30% barge-supplied case; the smaller shares are served by the existing road route.

Sheet OPEX
A1: ANNUAL OPERATING EXPENDITURE (IDR/year, real 2026)
A3: Fuel and consumable quantities are pulled from the INVENTORY sheet and multiplied by annual generation.
A5: Item | B5: Unit | C5: Baseline 0% | D5: Co-firing 5% | E5: Co-firing 10% | F5: Co-firing 20% | G5: Co-firing 30% (barge)
A6: Coal purchase | B6: IDR/yr | C6: =INVENTORY!C16*annual_mwh/1000*coal_price -> 7.5035874e+11 | D6: =INVENTORY!D16*annual_mwh/1000*coal_price -> 7.1938062e+11 | E6: =INVENTORY!E16*annual_mwh/1000*coal_price -> 6.8995834e+11 | F6: =INVENTORY!F16*annual_mwh/1000*coal_price -> 6.2490444e+11 | G6: =INVENTORY!G16*annual_mwh/1000*coal_price -> 5.5913828e+11
A7: PKS purchase | B7: IDR/yr | C7: =INVENTORY!C17*annual_mwh/1000*pks_price -> 0 | D7: =INVENTORY!D17*annual_mwh/1000*pks_price -> 4.967797e+10 | E7: =INVENTORY!E17*annual_mwh/1000*pks_price -> 1.0058635e+11 | F7: =INVENTORY!F17*annual_mwh/1000*pks_price -> 2.0498039e+11 | G7: =INVENTORY!G17*annual_mwh/1000*pks_price -> 3.1441348e+11
A8: Road transport surcharge | B8: IDR/yr | C8: =INVENTORY!C27*annual_mwh*truck_tariff -> 0 | D8: =INVENTORY!D27*annual_mwh*truck_tariff -> 6.8997181e+09 | E8: =INVENTORY!E27*annual_mwh*truck_tariff -> 1.3970327e+10 | F8: =INVENTORY!F27*annual_mwh*truck_tariff -> 4.2704249e+10 | G8: =INVENTORY!G27*annual_mwh*truck_tariff -> 2.6201123e+10
A9: Barge transport surcharge | B9: IDR/yr | C9: =INVENTORY!C28*annual_mwh*barge_tariff -> 0 | D9: =INVENTORY!D28*annual_mwh*barge_tariff -> 0 | E9: =INVENTORY!E28*annual_mwh*barge_tariff -> 0 | F9: =INVENTORY!F28*annual_mwh*barge_tariff -> 0 | G9: =INVENTORY!G28*annual_mwh*barge_tariff -> 3.912701e+10
A10: FGD limestone | B10: IDR/yr | C10: =INVENTORY!C31*annual_mwh/1000*limestone_price -> 2.7679356e+09 | D10: =INVENTORY!D31*annual_mwh/1000*limestone_price -> 2.6718735e+09 | E10: =INVENTORY!E31*annual_mwh/1000*limestone_price -> 2.5820016e+09 | F10: =INVENTORY!F31*annual_mwh/1000*limestone_price -> 2.3802974e+09 | G10: =INVENTORY!G31*annual_mwh/1000*limestone_price -> 2.1778131e+09
A11: Process water | B11: IDR/yr | C11: =INVENTORY!C32*annual_mwh*water_cost -> 1.383642e+10 | D11: =INVENTORY!D32*annual_mwh*water_cost -> 1.396336e+10 | E11: =INVENTORY!E32*annual_mwh*water_cost -> 1.413628e+10 | F11: =INVENTORY!F32*annual_mwh*water_cost -> 1.4403844e+10 | G11: =INVENTORY!G32*annual_mwh*water_cost -> 1.4729092e+10
A12: FABA disposal | B12: IDR/yr | C12: =INVENTORY!C33*annual_mwh/1000*faba_cost -> 9.0118639e+09 | D12: =INVENTORY!D33*annual_mwh/1000*faba_cost -> 8.9105999e+09 | E12: =INVENTORY!E33*annual_mwh/1000*faba_cost -> 8.8347284e+09 | F12: =INVENTORY!F33*annual_mwh/1000*faba_cost -> 8.6224587e+09 | G12: =INVENTORY!G33*annual_mwh/1000*faba_cost -> 8.4291019e+09
A13: Additional own-use electricity (drying and crushing) | B13: IDR/yr | C13: =INVENTORY!C26*annual_mwh*elec_price -> 0 | D13: =INVENTORY!D26*annual_mwh*elec_price -> 1.0977727e+09 | E13: =INVENTORY!E26*annual_mwh*elec_price -> 2.2227349e+09 | F13: =INVENTORY!F26*annual_mwh*elec_price -> 4.5296112e+09 | G13: =INVENTORY!G26*annual_mwh*elec_price -> 6.9478391e+09
A14: Fixed O&M uplift on the retrofit | B14: IDR/yr | C14: =CAPEX!C27*fom_rate -> 0 | D14: =CAPEX!D27*fom_rate -> 3.1004432e+09 | E14: =CAPEX!E27*fom_rate -> 5.0366848e+09 | F14: =CAPEX!F27*fom_rate -> 8.1821185e+09 | G14: =CAPEX!G27*fom_rate -> 12247500000
A15: Variable O&M uplift, biomass handling | B15: IDR/yr | C15: =INVENTORY!C17*annual_mwh/1000*vom_pks -> 0 | D15: =INVENTORY!D17*annual_mwh/1000*vom_pks -> 2.3183053e+09 | E15: =INVENTORY!E17*annual_mwh/1000*vom_pks -> 4.6940299e+09 | F15: =INVENTORY!F17*annual_mwh/1000*vom_pks -> 9.5657517e+09 | G15: =INVENTORY!G17*annual_mwh/1000*vom_pks -> 1.4672629e+10
A16: TOTAL ANNUAL OPEX | B16: IDR/yr | C16: =SUM(C6:C15) -> 7.7597496e+11 | D16: =SUM(D6:D15) -> 8.0802067e+11 | E16: =SUM(E6:E15) -> 8.4202148e+11 | F16: =SUM(F6:F15) -> 9.2027316e+11 | G16: =SUM(G6:G15) -> 9.9808387e+11
A17: Incremental OPEX vs baseline | B17: IDR/yr | C17: =C16-$C$16 -> 0 | D17: =D16-$C$16 -> 3.204571e+10 | E17: =E16-$C$16 -> 6.6046528e+10 | F17: =F16-$C$16 -> 1.4429821e+11 | G17: =G16-$C$16 -> 2.2210891e+11
A18: OPEX per MWh | B18: IDR/MWh | C18: =C16/annual_mwh -> 454264.7 | D18: =D16/annual_mwh -> 473024.63 | E18: =E16/annual_mwh -> 492929.1 | F18: =F16/annual_mwh -> 538738.53 | G18: =G16/annual_mwh -> 584289.82
A20: OPEX RATE INPUTS
A21: Rate | B21: Value | C21: Unit | D21: Basis
A22: Road freight tariff | B22: 1250 | C22: IDR/t.km | D22: Contracted 24 t lorry rate, Sumatra-Java corridor 2026
A23: Coastal barge tariff | B23: 320 | C23: IDR/t.km | D23: 3 000 DWT barge charter, bulk biomass
A24: Fixed O&M as share of retrofit CAPEX | B24: 0.03 | C24: fraction/yr | D24: Additional inspection, dust housekeeping, fire watch
A25: Variable O&M per tonne of PKS handled | B25: 42000 | C25: IDR/tonne | D25: Extra manning, wear parts, sampling and lab

Sheet CASH FLOW
A1: 25-YEAR INCREMENTAL CASH FLOW (IDR, real terms, discounted at the WACC)
A3: Year 0 carries the retrofit CAPEX; years 1-25 carry total annual OPEX. LCOE is the ratio of discounted cost to discounted energy.
A5: Year | B5: Discount factor | C5: Baseline 0% | D5: Co-firing 5% | E5: Co-firing 10% | F5: Co-firing 20% | G5: Co-firing 30% (barge)
A6: 0 | B6: =1/(1+wacc)^A6 -> 1 | C6: =-CAPEX!C27 -> 0 | D6: =-CAPEX!D27 -> -1.0334811e+11 | E6: =-CAPEX!E27 -> -1.6788949e+11 | F6: =-CAPEX!F27 -> -2.7273728e+11 | G6: =-CAPEX!G27 -> -408250000000
A7: 1 | B7: =1/(1+wacc)^A7 -> 0.90909091 | C7: =-OPEX!C16 -> -7.7597496e+11 | D7: =-OPEX!D16 -> -8.0802067e+11 | E7: =-OPEX!E16 -> -8.4202148e+11 | F7: =-OPEX!F16 -> -9.2027316e+11 | G7: =-OPEX!G16 -> -9.9808387e+11
A8: 2 | B8: =1/(1+wacc)^A8 -> 0.82644628 | C8: =-OPEX!C16 -> -7.7597496e+11 | D8: =-OPEX!D16 -> -8.0802067e+11 | E8: =-OPEX!E16 -> -8.4202148e+11 | F8: =-OPEX!F16 -> -9.2027316e+11 | G8: =-OPEX!G16 -> -9.9808387e+11
A9: 3 | B9: =1/(1+wacc)^A9 -> 0.7513148 | C9: =-OPEX!C16 -> -7.7597496e+11 | D9: =-OPEX!D16 -> -8.0802067e+11 | E9: =-OPEX!E16 -> -8.4202148e+11 | F9: =-OPEX!F16 -> -9.2027316e+11 | G9: =-OPEX!G16 -> -9.9808387e+11
A10: 4 | B10: =1/(1+wacc)^A10 -> 0.68301346 | C10: =-OPEX!C16 -> -7.7597496e+11 | D10: =-OPEX!D16 -> -8.0802067e+11 | E10: =-OPEX!E16 -> -8.4202148e+11 | F10: =-OPEX!F16 -> -9.2027316e+11 | G10: =-OPEX!G16 -> -9.9808387e+11
A11: 5 | B11: =1/(1+wacc)^A11 -> 0.62092132 | C11: =-OPEX!C16 -> -7.7597496e+11 | D11: =-OPEX!D16 -> -8.0802067e+11 | E11: =-OPEX!E16 -> -8.4202148e+11 | F11: =-OPEX!F16 -> -9.2027316e+11 | G11: =-OPEX!G16 -> -9.9808387e+11
A12: 6 | B12: =1/(1+wacc)^A12 -> 0.56447393 | C12: =-OPEX!C16 -> -7.7597496e+11 | D12: =-OPEX!D16 -> -8.0802067e+11 | E12: =-OPEX!E16 -> -8.4202148e+11 | F12: =-OPEX!F16 -> -9.2027316e+11 | G12: =-OPEX!G16 -> -9.9808387e+11
A13: 7 | B13: =1/(1+wacc)^A13 -> 0.51315812 | C13: =-OPEX!C16 -> -7.7597496e+11 | D13: =-OPEX!D16 -> -8.0802067e+11 | E13: =-OPEX!E16 -> -8.4202148e+11 | F13: =-OPEX!F16 -> -9.2027316e+11 | G13: =-OPEX!G16 -> -9.9808387e+11
A14: 8 | B14: =1/(1+wacc)^A14 -> 0.46650738 | C14: =-OPEX!C16 -> -7.7597496e+11 | D14: =-OPEX!D16 -> -8.0802067e+11 | E14: =-OPEX!E16 -> -8.4202148e+11 | F14: =-OPEX!F16 -> -9.2027316e+11 | G14: =-OPEX!G16 -> -9.9808387e+11
A15: 9 | B15: =1/(1+wacc)^A15 -> 0.42409762 | C15: =-OPEX!C16 -> -7.7597496e+11 | D15: =-OPEX!D16 -> -8.0802067e+11 | E15: =-OPEX!E16 -> -8.4202148e+11 | F15: =-OPEX!F16 -> -9.2027316e+11 | G15: =-OPEX!G16 -> -9.9808387e+11
A16: 10 | B16: =1/(1+wacc)^A16 -> 0.38554329 | C16: =-OPEX!C16 -> -7.7597496e+11 | D16: =-OPEX!D16 -> -8.0802067e+11 | E16: =-OPEX!E16 -> -8.4202148e+11 | F16: =-OPEX!F16 -> -9.2027316e+11 | G16: =-OPEX!G16 -> -9.9808387e+11
A17: 11 | B17: =1/(1+wacc)^A17 -> 0.3504939 | C17: =-OPEX!C16 -> -7.7597496e+11 | D17: =-OPEX!D16 -> -8.0802067e+11 | E17: =-OPEX!E16 -> -8.4202148e+11 | F17: =-OPEX!F16 -> -9.2027316e+11 | G17: =-OPEX!G16 -> -9.9808387e+11
A18: 12 | B18: =1/(1+wacc)^A18 -> 0.31863082 | C18: =-OPEX!C16 -> -7.7597496e+11 | D18: =-OPEX!D16 -> -8.0802067e+11 | E18: =-OPEX!E16 -> -8.4202148e+11 | F18: =-OPEX!F16 -> -9.2027316e+11 | G18: =-OPEX!G16 -> -9.9808387e+11
A19: 13 | B19: =1/(1+wacc)^A19 -> 0.28966438 | C19: =-OPEX!C16 -> -7.7597496e+11 | D19: =-OPEX!D16 -> -8.0802067e+11 | E19: =-OPEX!E16 -> -8.4202148e+11 | F19: =-OPEX!F16 -> -9.2027316e+11 | G19: =-OPEX!G16 -> -9.9808387e+11
A20: 14 | B20: =1/(1+wacc)^A20 -> 0.26333125 | C20: =-OPEX!C16 -> -7.7597496e+11 | D20: =-OPEX!D16 -> -8.0802067e+11 | E20: =-OPEX!E16 -> -8.4202148e+11 | F20: =-OPEX!F16 -> -9.2027316e+11 | G20: =-OPEX!G16 -> -9.9808387e+11
A21: 15 | B21: =1/(1+wacc)^A21 -> 0.23939205 | C21: =-OPEX!C16 -> -7.7597496e+11 | D21: =-OPEX!D16 -> -8.0802067e+11 | E21: =-OPEX!E16 -> -8.4202148e+11 | F21: =-OPEX!F16 -> -9.2027316e+11 | G21: =-OPEX!G16 -> -9.9808387e+11
A22: 16 | B22: =1/(1+wacc)^A22 -> 0.21762914 | C22: =-OPEX!C16 -> -7.7597496e+11 | D22: =-OPEX!D16 -> -8.0802067e+11 | E22: =-OPEX!E16 -> -8.4202148e+11 | F22: =-OPEX!F16 -> -9.2027316e+11 | G22: =-OPEX!G16 -> -9.9808387e+11
A23: 17 | B23: =1/(1+wacc)^A23 -> 0.19784467 | C23: =-OPEX!C16 -> -7.7597496e+11 | D23: =-OPEX!D16 -> -8.0802067e+11 | E23: =-OPEX!E16 -> -8.4202148e+11 | F23: =-OPEX!F16 -> -9.2027316e+11 | G23: =-OPEX!G16 -> -9.9808387e+11
A24: 18 | B24: =1/(1+wacc)^A24 -> 0.17985879 | C24: =-OPEX!C16 -> -7.7597496e+11 | D24: =-OPEX!D16 -> -8.0802067e+11 | E24: =-OPEX!E16 -> -8.4202148e+11 | F24: =-OPEX!F16 -> -9.2027316e+11 | G24: =-OPEX!G16 -> -9.9808387e+11
A25: 19 | B25: =1/(1+wacc)^A25 -> 0.16350799 | C25: =-OPEX!C16 -> -7.7597496e+11 | D25: =-OPEX!D16 -> -8.0802067e+11 | E25: =-OPEX!E16 -> -8.4202148e+11 | F25: =-OPEX!F16 -> -9.2027316e+11 | G25: =-OPEX!G16 -> -9.9808387e+11
A26: 20 | B26: =1/(1+wacc)^A26 -> 0.14864363 | C26: =-OPEX!C16 -> -7.7597496e+11 | D26: =-OPEX!D16 -> -8.0802067e+11 | E26: =-OPEX!E16 -> -8.4202148e+11 | F26: =-OPEX!F16 -> -9.2027316e+11 | G26: =-OPEX!G16 -> -9.9808387e+11
A27: 21 | B27: =1/(1+wacc)^A27 -> 0.13513057 | C27: =-OPEX!C16 -> -7.7597496e+11 | D27: =-OPEX!D16 -> -8.0802067e+11 | E27: =-OPEX!E16 -> -8.4202148e+11 | F27: =-OPEX!F16 -> -9.2027316e+11 | G27: =-OPEX!G16 -> -9.9808387e+11
A28: 22 | B28: =1/(1+wacc)^A28 -> 0.12284597 | C28: =-OPEX!C16 -> -7.7597496e+11 | D28: =-OPEX!D16 -> -8.0802067e+11 | E28: =-OPEX!E16 -> -8.4202148e+11 | F28: =-OPEX!F16 -> -9.2027316e+11 | G28: =-OPEX!G16 -> -9.9808387e+11
A29: 23 | B29: =1/(1+wacc)^A29 -> 0.11167816 | C29: =-OPEX!C16 -> -7.7597496e+11 | D29: =-OPEX!D16 -> -8.0802067e+11 | E29: =-OPEX!E16 -> -8.4202148e+11 | F29: =-OPEX!F16 -> -9.2027316e+11 | G29: =-OPEX!G16 -> -9.9808387e+11
A30: 24 | B30: =1/(1+wacc)^A30 -> 0.1015256 | C30: =-OPEX!C16 -> -7.7597496e+11 | D30: =-OPEX!D16 -> -8.0802067e+11 | E30: =-OPEX!E16 -> -8.4202148e+11 | F30: =-OPEX!F16 -> -9.2027316e+11 | G30: =-OPEX!G16 -> -9.9808387e+11
A31: 25 | B31: =1/(1+wacc)^A31 -> 0.092295998 | C31: =-OPEX!C16 -> -7.7597496e+11 | D31: =-OPEX!D16 -> -8.0802067e+11 | E31: =-OPEX!E16 -> -8.4202148e+11 | F31: =-OPEX!F16 -> -9.2027316e+11 | G31: =-OPEX!G16 -> -9.9808387e+11
A32: NPV cost | C32: =-SUMPRODUCT($B$6:$B$31,C6:C31) -> 7.0435557e+12 | D32: =-SUMPRODUCT($B$6:$B$31,D6:D31) -> 7.437784e+12 | E32: =-SUMPRODUCT($B$6:$B$31,E6:E31) -> 7.8109522e+12 | F32: =-SUMPRODUCT($B$6:$B$31,F6:F31) -> 8.6260936e+12 | G32: =-SUMPRODUCT($B$6:$B$31,G6:G31) -> 9.4678972e+12
